Workbook

Sheet 01.09.2025-30.09.2025(расход)
B1: Дата | C1: № | D1: сумма | E1: наименование | F1: кому
B2: 45901 | C2: 1 | D2: 83000 | E2: Ш холмага | F2: Благ-ть | H2: Дурбек | I2: =SUMIF(F2:F1042,"Д",D2:D1042) -> 735000 | K2: Благотвор-ть | L2: =SUMIF(F2:F1042,"Благ-ть",D2:D1042) -> 533878 | N2: Авто + бензин | O2: =SUMIF(F2:F1042,"авто",D2:D1042) -> 15000 | R2: Сбер | S2: =Касса!G6 -> 4500000
B3: 45902 | C3: 1 | D3: 170000 | E3: аптека | F3: здр | H3: Сарвиноз | I3: =SUMIF(F2:F1041,"С",D2:D1041) -> 181000 | K3: Де-факто | L3: =SUMIF(F2:F1132,"др.",D2:D1042) -> 550000 | N3: Одежда | O3: =SUMIF(F3:F1132,"одежда",D3:D1132) -> 0
C4: 2 | D4: 93000 | E4: д | F4: Д | H4: Домой | I4: =SUMIF(F2:F1132,"домой",D2:D1033) -> 3300000 | K4: Папе | L4: =SUMIF(F2:F1132,"Папа",D2:D1042) -> 950000 | N4: На оборот | O4: =SUMIF(F2:F1037,"н/о",D2:D1037) -> 0
B5: 45912 | C5: 1 | D5: 145000 | E5: ингаляц | F5: здр | H5: Ком-ые/услуги | I5: =SUMIF(F2:F1043,"к/у",D2:D1043) -> 30000 | K5: Разв-ие/обуч | L5: =SUMIF(F2:F1132,"разв",D2:D1132) -> 0 | N5: МухаммадУмар | O5: =SUMIF(F2:F1037,"Умар",D2:D1037) -> 230000
C6: 2 | D6: 5000 | E6: сув | F6: Д | H6: Самир | I6: =SUMIF(F2:F1045,"Сам",D2:D1046) -> 199000 | K6: Здоровье | L6: =SUMIF(F3:F1041,"здр",D3:D1041) -> 761000 | N6: Рабочие расх-ы | O6: =SUMIF(F2:F1039,"раб/рас",D2:D1039) -> 0 | R6: Нал | S6: =D20+D27+D53+D70 -> 235000
C7: 3 | D7: 30000 | E7: Обед | F7: Д | H7: Мама | I7: =SUMIF(F2:F1132,"М",D2:D1042) -> 900000 | K7: Рассрочка | L7: =SUMIF(F2:F1032,"р-ка",D2:D1039) -> 0 | N7: Инвестиции | O7: =SUMIF(F2:F1040,"инвест",D2:D1040) -> 1250000
B8: 45913 | C8: 1 | D8: 150000 | E8: Сарвиноз Уй | F8: Благ-ть | H8: Сбережения | I8: =SUMIF(F2:F1032,"С-я",D2:D1039) -> 4500000 | K8: Неизвест траты | L8: =SUMIF(F5:F1132,"растрата",D5:D1042) -> 130000 | N8: Обналичка | O8: =(SUMIF(F2:F1040,"обнал",D2:D1040)) -> 235000
C9: 2 | D9: 108000 | E9: обед | F9: Д | N9: Итого: | O9: =SUM(I2:I8,L2:L8,O2:O8) -> 14499878
C10: 3 | D10: 100000 | E10: Сар йог | F10: домой | H10: Итого: | I10: =SUM(D2:D1041) -> 14499878 | N10: итого по смете | O10: =SUM(I2:I7,L2:L7,O2:O7) -> 9634878
C11: 4 | D11: 150000 | E11: Самирга кийим | F11: Сам | H11: Итого: | I11: =SUM(I2:I8,L2:L8,O2:O8) -> 14499878
C12: 5 | D12: 230000 | E12: Памперс Умар | F12: Умар | H12: Разница: | I12: =I10-I11 -> 0
C13: 6 | D13: 300000 | E13: Продукты | F13: домой
B14: 45914 | C14: 1 | D14: 50000 | E14: Сарвиноз | F14: С
C15: 2 | D15: 65878 | E15: Продукты ёрмозорга | F15: Благ-ть
C16: 3 | D16: 165000 | E16: Интернет | F16: домой
C17: 4 | D17: 150000 | E17: Догрига дадамга | F17: Папа
C18: 5 | D18: 100000 | E18: Гостиница брон | F18: Папа
C19: 6 | D19: 36000 | E19: Догри | F19: здр
B20: 45915 | C20: 1 | D20: =200000-D21-D22-D26-D25 -> 0 | E20: обнал | F20: обнал
C21: 2 | D21: 50000 | E21: Обед | F21: Д
C22: 3 | D22: 15000 | E22: мойка | F22: авто
C23: 4 | D23: 400000 | E23: папа в таш | F23: папа
B24: 45916 | C24: 1 | D24: 100000 | E24: Элевит | F24: С
C25: 2 | D25: 100000 | E25: Чеварга | F25: М
B26: 45917 | C26: 1 | D26: 35000 | E26: Обед | F26: Д
C27: 2 | D27: =400000-D29-D37-D38 -> 5000 | E27: нал бозорга | F27: обнал
C28: 3 | D28: =294000+388000+7000 -> 689000 | E28: продукты | F28: домой
C29: 4 | D29: 180000 | E29: продукты | F29: домой
C30: 5 | D30: 75000 | E30: сув | F30: домой
B31: 45918 | C31: 1 | D31: 37000 | E31: продукты | F31: домой
B32: 45919 | C32: 1 | D32: 20000 | E32: пульт | F32: домой
C33: 2 | D33: 50000 | E33: ремешок | F33: Д
C34: 3 | D34: 30000 | E34: Остатка узум карта | F34: домой
B35: 45920 | C35: 1 | D35: 200000 | E35: Маме | F35: М
C36: 2 | D36: 36000 | E36: аптека | F36: здр
C37: 3 | D37: 80000 | E37: Ош водий состав | F37: Д
C38: 4 | D38: 135000 | E38: Ш.ака | F38: Благ-ть
B39: 45921 | C39: 1 | D39: 12000 | E39: батарейка | F39: домой
C40: 2 | D40: 218000 | E40: гушт | F40: домой
...

Sheet 01.09.2025-30.09.2025 (приход)
B2: Дата | C2: № | D2: сумма | E2: наименование | F2: кому | H2: кому | I2: сумма
B3: 45900 | C3: 1 | D3: 346000 | E3: *9872 | F3: ост. | H3: З/П | I3: =SUMIF(F3:F101,"з/п",D3:D101) -> 14377000
B4: 45912 | C4: 1 | D4: 1074000 | E4: *2991 | F4: з/п | H4: Мама | I4: =SUMIF(F3:F102,"М",D3:D102) -> 0
B5: 45913 | C5: 1 | D5: 3685000 | E5: *2991 | F5: з/п | H5: др. | I5: =SUMIF(F3:F103,"др.",D3:D103) -> 0
B6: 45917 | C6: 1 | D6: 618000 | E6: *2991 | F6: з/п | H6: Премия | I6: =SUMIF(F3:F104,"пр.",D3:D104) -> 0
B7: 45923 | C7: 1 | D7: 9000000 | E7: *2991 | F7: з/п | H7: ост. на начало | I7: =SUMIF(F3:F105,"ост.",D3:D105) -> 346000
B8: 45926 | C8: 1 | D8: 500000 | E8: Нал | F8: раб/дох | H8: раб. Доходы | I8: =SUMIF(F3:F108,"раб/дох",D3:D108) -> 550000
B9: 45930 | C9: 1 | D9: 50000 | E9: нал | F9: раб/дох | H9: С оборота | I9: 0
H11: Аренда | I11: =SUMIF(F5:F110,"обор",D5:D110) -> 0
H14: ИТОГО: | I14: =SUM(I3:I11) -> 15273000
B23: Итого | C23: : | D23: =SUM(D3:D19) -> 15273000
B24: Разница | C24: : | D24: =D23-I14 -> 0

Sheet 01.09.2025-30.09.2025(смета)
B2: Ожидаемые приходы | H2: Фактические приходы
B4: Доходы | E4: Расходы | H4: Доходы | K4: Расходы
B5: Дурбек з/п | C5: 17980000 | E5: ='01.09.2025-30.09.2025(расход)'!H2 -> Дурбек | F5: 1500000 | H5: Дурбек | I5: ='01.09.2025-30.09.2025 (приход)'!I3 -> 14377000 | K5: ='01.09.2025-30.09.2025(расход)'!H2 -> Дурбек | L5: ='01.09.2025-30.09.2025(расход)'!I2 -> 735000
C6: - | E6: ='01.09.2025-30.09.2025(расход)'!H3 -> Сарвиноз | F6: 200000 | H6: ='01.09.2025-30.09.2025 (приход)'!H4 -> Мама | I6: ='01.09.2025-30.09.2025 (приход)'!I4 -> 0 | K6: ='01.09.2025-30.09.2025(расход)'!H3 -> Сарвиноз | L6: ='01.09.2025-30.09.2025(расход)'!I3 -> 181000
C7: - | E7: ='01.09.2025-30.09.2025(расход)'!H4 -> Домой | F7: 2300000 | H7: др. | I7: ='01.09.2025-30.09.2025 (приход)'!I5 -> 0 | K7: ='01.09.2025-30.09.2025(расход)'!H4 -> Домой | L7: ='01.09.2025-30.09.2025(расход)'!I4 -> 3300000
B8: Премия | E8: ='01.09.2025-30.09.2025(расход)'!H5 -> Ком-ые/услуги | F8: 1000000 | H8: Премия | I8: ='01.09.2025-30.09.2025 (приход)'!I6 -> 0 | K8: ='01.09.2025-30.09.2025(расход)'!H5 -> Ком-ые/услуги | L8: ='01.09.2025-30.09.2025(расход)'!I5 -> 30000
E9: ='01.09.2025-30.09.2025(расход)'!N5 -> МухаммадУмар | F9: 300000 | H9: Аренда | I9: ='01.09.2025-30.09.2025 (приход)'!I11 -> 0 | K9: =E9 -> МухаммадУмар | L9: ='01.09.2025-30.09.2025(расход)'!O5 -> 230000
E10: ='01.09.2025-30.09.2025(расход)'!H6 -> Самир | H10: ост. на начало | I10: ='01.09.2025-30.09.2025 (приход)'!I7 -> 346000 | K10: ='01.09.2025-30.09.2025(расход)'!H6 -> Самир | L10: ='01.09.2025-30.09.2025(расход)'!I6 -> 199000
E11: ='01.09.2025-30.09.2025(расход)'!H7 -> Мама | F11: 300000 | H11: раб. Доходы | I11: ='01.09.2025-30.09.2025 (приход)'!I8 -> 550000 | K11: ='01.09.2025-30.09.2025(расход)'!H7 -> Мама | L11: ='01.09.2025-30.09.2025(расход)'!I7 -> 900000
E12: ='01.09.2025-30.09.2025(расход)'!K2 -> Благотвор-ть | F12: 500000 | H12: С оборота | I12: ='01.09.2025-30.09.2025 (приход)'!I9 -> 0 | K12: ='01.09.2025-30.09.2025(расход)'!K2 -> Благотвор-ть | L12: ='01.09.2025-30.09.2025(расход)'!L2 -> 533878
E13: ='01.09.2025-30.09.2025(расход)'!K3 -> Де-факто | F13: 500000 | K13: ='01.09.2025-30.09.2025(расход)'!K3 -> Де-факто | L13: ='01.09.2025-30.09.2025(расход)'!L3 -> 550000
E14: ='01.09.2025-30.09.2025(расход)'!K4 -> Папе | F14: 300000 | K14: ='01.09.2025-30.09.2025(расход)'!K4 -> Папе | L14: ='01.09.2025-30.09.2025(расход)'!L4 -> 950000
E15: ='01.09.2025-30.09.2025(расход)'!K6 -> Здоровье | F15: 500000 | K15: ='01.09.2025-30.09.2025(расход)'!K6 -> Здоровье | L15: ='01.09.2025-30.09.2025(расход)'!L6 -> 761000
E16: ='01.09.2025-30.09.2025(расход)'!K7 -> Рассрочка | K16: ='01.09.2025-30.09.2025(расход)'!N8 -> Обналичка | L16: ='01.09.2025-30.09.2025(расход)'!S6 -> 235000
E17: ='01.09.2025-30.09.2025(расход)'!N2 -> Авто + бензин | F17: 300000 | K17: ='01.09.2025-30.09.2025(расход)'!K7 -> Рассрочка | L17: ='01.09.2025-30.09.2025(расход)'!L7 -> 0
E18: Одежда | K18: ='01.09.2025-30.09.2025(расход)'!N2 -> Авто + бензин | L18: ='01.09.2025-30.09.2025(расход)'!O2 -> 15000
E19: Инвестиции | F19: 1000000 | K19: Одежда | L19: ='01.09.2025-30.09.2025(расход)'!O3 -> 0
E20: =K23 -> Сбережения | F20: 9000000 | K20: ='01.09.2025-30.09.2025(расход)'!K5 -> Разв-ие/обуч | L20: ='01.09.2025-30.09.2025(расход)'!L5 -> 0
K21: неизвет/рас | L21: ='01.09.2025-30.09.2025(расход)'!L8 -> 130000
K22: рабочие расх | L22: ='01.09.2025-30.09.2025(расход)'!O6 -> 0
K23: ='01.09.2025-30.09.2025(расход)'!H8 -> Сбережения | L23: ='01.09.2025-30.09.2025(расход)'!I8 -> 4500000
K24: Инвестиции | L24: ='01.09.2025-30.09.2025(расход)'!O7 -> 1250000
B26: ИТОГО: | C26: =SUM(C5:C16) -> 17980000 | E26: ИТОГО: | F26: =SUM(F5:F20) -> 17700000 | H26: ИТОГО: | I26: =SUM(I5:I18) -> 15273000 | K26: ИТОГО (по смете): | L26: =SUM(L5:L15,L24,L17:L22)-500000 -> 9264878 | M26: =L26-L19-1200000 -> 8064878
K27: ИТОГО: | L27: =SUM(L5:L25) -> 14499878
B29: Разница: | C29: =(C26-F26) -> 280000 | H29: Разница: | I29: =(I26-L27) -> 773122 | M29: 11000 недостача 01/10
H30: Наличка: | I30: =L16 -> 235000

Sheet Касса
B4: Касса | F4: =SUM(SUM(D6:D32))-(SUM(E7:E32)) -> 350 | G4: в Суммах
B5: Дата | C5: № | D5: Приход | E5: Расход | F5: Откуда/куда
B6: 45924 | C6: 1 | D6: 366 | F6: з/п | G6: ='01.09.2025-30.09.2025(расход)'!D50 -> 4500000
C7: 2 | E7: =16-E8 -> 0 | F7: ост на карте
B8: 45928 | E8: 16 | F8: расход с карты
